Workbook

Sheet Data & Returns
A1: Week | B1: Date | C1: S&P 500 Price | D1: AAPL Price | E1: S&P 500 Log Return | F1: AAPL Log Return
A2: 1 | B2: 45963 | C2: 6771.74 | D2: 270.04
A3: 2 | B3: 45956 | C3: 6840.2 | D3: 270.37 | E3: =LN(C3/C2) | F3: =LN(D3/D2)
A4: 3 | B4: 45949 | C4: 6791.69 | D4: 262.82 | E4: =LN(C4/C3) | F4: =LN(D4/D3)
A5: 4 | B5: 45942 | C5: 6664.01 | D5: 252.29 | E5: =LN(C5/C4) | F5: =LN(D5/D4)
A6: 5 | B6: 45935 | C6: 6552.51 | D6: 245.27 | E6: =LN(C6/C5) | F6: =LN(D6/D5)
A7: 6 | B7: 45928 | C7: 6715.79 | D7: 258.02 | E7: =LN(C7/C6) | F7: =LN(D7/D6)
A8: 7 | B8: 45921 | C8: 6643.7 | D8: 255.46 | E8: =LN(C8/C7) | F8: =LN(D8/D7)
A9: 8 | B9: 45914 | C9: 6664.36 | D9: 245.5 | E9: =LN(C9/C8) | F9: =LN(D9/D8)
A10: 9 | B10: 45907 | C10: 6584.29 | D10: 234.07 | E10: =LN(C10/C9) | F10: =LN(D10/D9)
A11: 10 | B11: 45900 | C11: 6481.5 | D11: 239.69 | E11: =LN(C11/C10) | F11: =LN(D11/D10)
A12: 11 | B12: 45893 | C12: 6460.26 | D12: 232.14 | E12: =LN(C12/C11) | F12: =LN(D12/D11)
A13: 12 | B13: 45886 | C13: 6466.91 | D13: 227.76 | E13: =LN(C13/C12) | F13: =LN(D13/D12)
A14: 13 | B14: 45879 | C14: 6449.8 | D14: 231.59 | E14: =LN(C14/C13) | F14: =LN(D14/D13)
... A315: 314 | B315: 43772 | C315: 3093.08 | D315: 65.04 | E315: =LN(C315/C314) | F315: =LN(D315/D314)
A316: 315 | B316: 43765 | C316: 3066.91 | E316: =LN(C316/C315) | F316: =LN(D316/D315)
A317: 316 | B317: 43758 | C317: 3022.55 | E317: =LN(C317/C316) | F317: =LN(D317/D316)
A318: 317 | B318: 43751 | C318: 2986.2 | E318: =LN(C318/C317) | F318: =LN(D318/D317)
A319: 318 | B319: 43744 | C319: 2970.27 | E319: =LN(C319/C318) | F319: =LN(D319/D318)
A320: 319 | B320: 43737 | C320: 2952.01 | E320: =LN(C320/C319) | F320: =LN(D320/D319)
A321: 320 | B321: 43730 | C321: 2961.79 | E321: =LN(C321/C320) | F321: =LN(D321/D320)
A322: 321 | B322: 43723 | C322: 2992.07 | E322: =LN(C322/C321) | F322: =LN(D322/D321)
A323: 322 | B323: 43716 | C323: 3007.39 | E323: =LN(C323/C322) | F323: =LN(D323/D322)
A324: 323 | B324: 43709 | C324: 2978.71 | E324: =LN(C324/C323) | F324: =LN(D324/D323)
A325: 324 | B325: 43702 | C325: 2926.46 | E325: =LN(C325/C324) | F325: =LN(D325/D324)
A326: 325 | B326: 43695 | C326: 2847.11 | E326: =LN(C326/C325) | F326: =LN(D326/D325)
A327: 326 | B327: 43688 | C327: 2888.68 | E327: =LN(C327/C326) | F327: =LN(D327/D326)
... A358: 357 | B358: 43471 | C358: 2596.26 | E358: =LN(C358/C357) | F358: =LN(D358/D357)

Sheet Calculations
A1: (a) MEAN WEEKLY LOG RETURN
A2: Calculation Method | B2: S&P 500 | C2: AAPL
A3: Excel AVERAGE function | B3: =AVERAGE('Data & Returns'!E3:E358) | C3: =AVERAGE('Data & Returns'!F3:F358)
A5: (b) VARIANCE
A6: Calculation Method | B6: S&P 500 | C6: AAPL
A7: Manual: Σ(x - mean)²/N | B7: =SUMPRODUCT(('Data & Returns'!E3:E358-B6)^2)/COUNT('Data & Returns'!E3:E358) | C7: =SUMPRODUCT(('Data & Returns'!F3:F358-C6)^2)/COUNT('Data & Returns'!F3:F358)
A8: Excel VAR.P function | B8: =VAR.P('Data & Returns'!E3:E358) | C8: =VAR.P('Data & Returns'!F3:F358)
A9: Difference (should be ≈0) | B9: =ABS(B7-B8) | C9: =ABS(C7-C8)
A11: (c) STANDARD DEVIATION
A12: Calculation Method | B12: S&P 500 | C12: AAPL
A13: Manual: SQRT(Variance) | B13: =SQRT(B9) | C13: =SQRT(C9)
A14: Excel STDEV.P function | B14: =STDEV.P('Data & Returns'!E3:E358) | C14: =STDEV.P('Data & Returns'!F3:F358)
A15: Difference (should be ≈0) | B15: =ABS(B13-B14) | C15: =ABS(C13-C14)
A17: (e) SKEWNESS AND KURTOSIS
A18: Calculation Method | B18: S&P 500 | C18: AAPL
A19: Skewness (Excel SKEW) | B19: =SKEW('Data & Returns'!E3:E358) | C19: =SKEW('Data & Returns'!F3:F358)
A20: Kurtosis (Excel KURT) | B20: =KURT('Data & Returns'!E3:E358) | C20: =KURT('Data & Returns'!F3:F358)
A22: (f) WEEKS MOVING TOGETHER/APART
A23: Movement Pattern | B23: Count | C23: Proportion
A24: Weeks moving together (same sign) | B24: =SUMPRODUCT((SIGN('Data & Returns'!E3:E358)=SIGN('Data & Returns'!F3:F358))*1) | C24: =B24/COUNT('Data & Returns'!E3:E358)
A25: Weeks moving apart (opposite sign) | B25: =SUMPRODUCT((SIGN('Data & Returns'!E3:E358)<>SIGN('Data & Returns'!F3:F358))*1) | C25: =B25/COUNT('Data & Returns'!E3:E358)
A27: (g) COVARIANCE
A28: Calculation Method | B28: Value
A29: Manual: Σ(x-mean_x)(y-mean_y)/N | B29: =SUMPRODUCT(('Data & Returns'!E3:E358-B6),('Data & Returns'!F3:F358-C6))/COUNT('Data & Returns'!E3:E358)
A30: Excel COVARIANCE.P function | B30: =COVARIANCE.P('Data & Returns'!E3:E358,'Data & Returns'!F3:F358)
A31: Difference (should be ≈0) | B31: =ABS(B29-B30)
A33: (h) CORRELATION
A34: Calculation Method | B34: Value
A35: Manual: Cov(x,y)/(StdDev_x × StdDev_y) | B35: =B25/(B18*C18)
A36: Excel CORREL function | B36: =CORREL('Data & Returns'!E3:E358,'Data & Returns'!F3:F358)
A37: Difference (should be ≈0) | B37: =ABS(B35-B36)
A39: (j) REGRESSION STATISTICS (AAPL vs S&P 500)
A40: Statistic | B40: Value | C40: Excel Function Used
A41: Slope (Beta) | B41: =SLOPE('Data & Returns'!F3:F358,'Data & Returns'!E3:E358) | C41: SLOPE(y_range, x_range)
A42: Intercept (Alpha) | B42: =INTERCEPT('Data & Returns'!F3:F358,'Data & Returns'!E3:E358) | C42: INTERCEPT(y_range, x_range)
A43: R-Square | B43: =RSQ('Data & Returns'!F3:F358,'Data & Returns'!E3:E358) | C43: RSQ(y_range, x_range)
A44: Verification: R² = Correlation² | B44: =B43-B33^2 | C44: Should be ≈0

Sheet Histograms
A1: S&P 500 RETURNS HISTOGRAM
A2: Bin (Upper Limit) | B2: Frequency
A3: -0.15 | B3: =COUNTIF('Data & Returns'!E3:E358,"<="&A3)
A4: -0.14 | B4: =COUNTIFS('Data & Returns'!E3:E358,">"&A3,'Data & Returns'!E3:E358,"<="&A4)
A5: -0.13 | B5: =COUNTIFS('Data & Returns'!E3:E358,">"&A4,'Data & Returns'!E3:E358,"<="&A5)
A6: -0.12 | B6: =COUNTIFS('Data & Returns'!E3:E358,">"&A5,'Data & Returns'!E3:E358,"<="&A6)
A7: -0.11 | B7: =COUNTIFS('Data & Returns'!E3:E358,">"&A6,'Data & Returns'!E3:E358,"<="&A7)
A8: -0.1 | B8: =COUNTIFS('Data & Returns'!E3:E358,">"&A7,'Data & Returns'!E3:E358,"<="&A8)
A9: -0.09 | B9: =COUNTIFS('Data & Returns'!E3:E358,">"&A8,'Data & Returns'!E3:E358,"<="&A9)
A10: -0.08 | B10: =COUNTIFS('Data & Returns'!E3:E358,">"&A9,'Data & Returns'!E3:E358,"<="&A10)
A11: -0.07 | B11: =COUNTIFS('Data & Returns'!E3:E358,">"&A10,'Data & Returns'!E3:E358,"<="&A11)
A12: -0.06 | B12: =COUNTIFS('Data & Returns'!E3:E358,">"&A11,'Data & Returns'!E3:E358,"<="&A12)
A13: -0.05 | B13: =COUNTIFS('Data & Returns'!E3:E358,">"&A12,'Data & Returns'!E3:E358,"<="&A13)
A14: -0.04 | B14: =COUNTIFS('Data & Returns'!E3:E358,">"&A13,'Data & Returns'!E3:E358,"<="&A14)
A15: -0.03 | B15: =COUNTIFS('Data & Returns'!E3:E358,">"&A14,'Data & Returns'!E3:E358,"<="&A15)
A16: -0.02 | B16: =COUNTIFS('Data & Returns'!E3:E358,">"&A15,'Data & Returns'!E3:E358,"<="&A16)
A17: -0.01 | B17: =COUNTIFS('Data & Returns'!E3:E358,">"&A16,'Data & Returns'!E3:E358,"<="&A17)
A18: 1.3877788e-16 | B18: =COUNTIFS('Data & Returns'!E3:E358,">"&A17,'Data & Returns'!E3:E358,"<="&A18)
A19: 0.01 | B19: =COUNTIFS('Data & Returns'!E3:E358,">"&A18,'Data & Returns'!E3:E358,"<="&A19)
A20: 0.02 | B20: =COUNTIFS('Data & Returns'!E3:E358,">"&A19,'Data & Returns'!E3:E358,"<="&A20)
A21: 0.03 | B21: =COUNTIFS('Data & Returns'!E3:E358,">"&A20,'Data & Returns'!E3:E358,"<="&A21)
A22: 0.04 | B22: =COUNTIFS('Data & Returns'!E3:E358,">"&A21,'Data & Returns'!E3:E358,"<="&A22)
A23: 0.05 | B23: =COUNTIFS('Data & Returns'!E3:E358,">"&A22,'Data & Returns'!E3:E358,"<="&A23)
A24: 0.06 | B24: =COUNTIFS('Data & Returns'!E3:E358,">"&A23,'Data & Returns'!E3:E358,"<="&A24)
A25: 0.07 | B25: =COUNTIFS('Data & Returns'!E3:E358,">"&A24,'Data & Returns'!E3:E358,"<="&A25)
A26: 0.08 | B26: =COUNTIFS('Data & Returns'!E3:E358,">"&A25,'Data & Returns'!E3:E358,"<="&A26)
A27: 0.09 | B27: =COUNTIFS('Data & Returns'!E3:E358,">"&A26,'Data & Returns'!E3:E358,"<="&A27)
A28: 0.1 | B28: =COUNTIFS('Data & Returns'!E3:E358,">"&A27,'Data & Returns'!E3:E358,"<="&A28)
A29: 0.11 | B29: =COUNTIFS('Data & Returns'!E3:E358,">"&A28,'Data & Returns'!E3:E358,"<="&A29)
A30: 0.12 | B30: =COUNTIFS('Data & Returns'!E3:E358,">"&A29,'Data & Returns'!E3:E358,"<="&A30)
A31: 0.13 | B31: =COUNTIFS('Data & Returns'!E3:E358,">"&A30,'Data & Returns'!E3:E358,"<="&A31)
A32: 0.14 | B32: =COUNTIFS('Data & Returns'!E3:E358,">"&A31,'Data & Returns'!E3:E358,"<="&A32)
A33: 0.15 | B33: =COUNTIFS('Data & Returns'!E3:E358,">"&A32,'Data & Returns'!E3:E358,"<="&A33)
A36: AAPL RETURNS HISTOGRAM
A37: Bin (Upper Limit) | B37: Frequency
A38: -0.2 | B38: =COUNTIF('Data & Returns'!F3:F358,"<="&A38)
A39: -0.19 | B39: =COUNTIFS('Data & Returns'!F3:F358,">"&A38,'Data & Returns'!F3:F358,"<="&A39)
A40: -0.18 | B40: =COUNTIFS('Data & Returns'!F3:F358,">"&A39,'Data & Returns'!F3:F358,"<="&A40)
A41: -0.17 | B41: =COUNTIFS('Data & Returns'!F3:F358,">"&A40,'Data & Returns'!F3:F358,"<="&A41)
A42: -0.16 | B42: =COUNTIFS('Data & Returns'!F3:F358,">"&A41,'Data & Returns'!F3:F358,"<="&A42)
...

Sheet Summary Results
A1: QUESTION 2: STATISTICAL ANALYSIS SUMMARY
A3: Dataset Information
A4: Stock Selected: | B4: Apple Inc. (AAPL)
A5: Index Selected: | B5: S&P 500
A6: Data Frequency: | B6: Weekly
A7: Period: | B7: November 2019 to November 2025 (6 years)
A8: Number of Observations: | B8: =COUNT('Data & Returns'!E3:E358) & " weekly returns"
A10: Statistical Summary
A11: Metric | B11: S&P 500 | C11: AAPL
A12: Mean Weekly Return | B12: =Calculations!B6 | C12: =Calculations!C6
A13: Variance | B13: =Calculations!B11 | C13: =Calculations!C11
A14: Standard Deviation | B14: =Calculations!B17 | C14: =Calculations!C17
A15: Skewness | B15: =Calculations!B23 | C15: =Calculations!C23
A16: Kurtosis | B16: =Calculations!B24 | C16: =Calculations!C24
A18: Co-movement Analysis
A19: Weeks Moving Together | B19: =Calculations!B28 | C19: =Calculations!C28
A20: Weeks Moving Apart | B20: =Calculations!B29 | C20: =Calculations!C29
A22: Relationship Metrics
A23: Covariance | B23: =Calculations!B33
A24: Correlation | B24: =Calculations!B38
A26: Regression Results (AAPL vs S&P 500)
A27: Beta (Slope) | B27: =Calculations!B43
A28: Alpha (Intercept) | B28: =Calculations!B44
A29: R-Square | B29: =Calculations!B45
